Workbook

Sheet Guide Sheet
A1: PyPSA Model Notebook
A3: Sheet Name | B3: Links | C3: Data Description | D3: Data Type
A4: buses | B4: =HYPERLINK("#'" & A4 & "'!A2", "Go to " & A4) -> Go to buses | C4: component characteristics | D4: static
A5: carriers | B5: =HYPERLINK("#'" & A5 & "'!A2", "Go to " & A5) -> Go to carriers | C5: component characteristics | D5: static
A6: generators | B6: =HYPERLINK("#'" & A6 & "'!A2", "Go to " & A6) -> Go to generators | C6: component characteristics | D6: static
A7: generators-p_max_pu | B7: =HYPERLINK("#'" & A7 & "'!A2", "Go to " & A7) -> Go to generators-p_max_pu | C7: time series data | D7: varying
A8: generators-p_min_pu | B8: =HYPERLINK("#'" & A8 & "'!A2", "Go to " & A8) -> Go to generators-p_min_pu | C8: time series data | D8: varying
A9: generators-p_set | B9: =HYPERLINK("#'" & A9 & "'!A2", "Go to " & A9) -> Go to generators-p_set | C9: time series data | D9: static
A10: links | B10: =HYPERLINK("#'" & A10 & "'!A2", "Go to " & A10) -> Go to links | C10: component characteristics | D10: static
A11: links-p_max_pu | B11: =HYPERLINK("#'" & A11 & "'!A2", "Go to " & A11) -> Go to links-p_max_pu | C11: time series data | D11: varying
A12: links-p_min_pu | B12: =HYPERLINK("#'" & A12 & "'!A2", "Go to " & A12) -> Go to links-p_min_pu | C12: time series data | D12: varying
A13: links-p_set | B13: =HYPERLINK("#'" & A13 & "'!A2", "Go to " & A13) -> Go to links-p_set | C13: time series data | D13: varying
A14: loads | B14: =HYPERLINK("#'" & A14 & "'!A2", "Go to " & A14) -> Go to loads | C14: component characteristics | D14: static
A15: loads-p_set | B15: =HYPERLINK("#'" & A15 & "'!A2", "Go to " & A15) -> Go to loads-p_set | C15: time series data | D15: varying
... A19: stores | B19: =HYPERLINK("#'" & A19 & "'!A2", "Go to " & A19) -> Go to stores | C19: component characteristics | D19: static
A20: var-buses | B20: =HYPERLINK("#'" & A20 & "'!A2", "Go to " & A20) -> Go to var-buses | C20: component attributes
A21: var-carriers | B21: =HYPERLINK("#'" & A21 & "'!A2", "Go to " & A21) -> Go to var-carriers | C21: component attributes
A22: var-generators | B22: =HYPERLINK("#'" & A22 & "'!A2", "Go to " & A22) -> Go to var-generators | C22: component attributes
A23: var-links | B23: =HYPERLINK("#'" & A23 & "'!A2", "Go to " & A23) -> Go to var-links | C23: component attributes
A24: var-loads | B24: =HYPERLINK("#'" & A24 & "'!A2", "Go to " & A24) -> Go to var-loads | C24: component attributes
A25: var-networks | B25: =HYPERLINK("#'" & A25 & "'!A2", "Go to " & A25) -> Go to var-networks | C25: component attributes
A26: var-storage_units | B26: =HYPERLINK("#'" & A26 & "'!A2", "Go to " & A26) -> Go to var-storage_units | C26: component attributes
A27: var-stores | B27: =HYPERLINK("#'" & A27 & "'!A2", "Go to " & A27) -> Go to var-stores | C27: component attributes

Sheet River Inflow Data (Backup)
A1: Hour of year | B1: Grey Kirk Inflow
A2: 1 | B2: 46.800001
A3: 2 | B3: 46.800001
A4: =A3+1 -> 3 | B4: 46.800001
A5: =A4+1 -> 4 | B5: 46.800001
A6: =A5+1 -> 5 | B6: 46.800001
A7: =A6+1 -> 6 | B7: 46.800001
A8: =A7+1 -> 7 | B8: 46.800001
A9: =A8+1 -> 8 | B9: 46.800001
A10: =A9+1 -> 9 | B10: 46.800001
A11: =A10+1 -> 10 | B11: 46.800001
A12: =A11+1 -> 11 | B12: 46.800001
A13: =A12+1 -> 12 | B13: 46.800001
A14: =A13+1 -> 13 | B14: 46.800001
A15: =A14+1 -> 14 | B15: 46.800001
... A8761: =A8760+1 -> 8760 | B8761: 2087.9999

Sheet buses
A1: name | B1: carrier | C1: x | D1: y
A2: EC | B2: AC | C2: 26.4194 | D2: -32.2968
A3: FS | B3: AC | C3: 26.8141 | D3: -28.4541
A4: GP | B4: AC | C4: 28.2184 | D4: -26.2708
A5: ZN | B5: AC | C5: 30.5595 | D5: -28.5306
A6: LP | B6: AC | C6: 29.8739 | D6: -23.4015
A7: MP | B7: AC | C7: 30.4044 | D7: -25.5653
A8: NW | B8: AC | C8: 25.7906 | D8: -26.4649
A9: NC | B9: AC | C9: 21.8569 | D9: -29.046
A10: WC | B10: AC | C10: 19.4294 | D10: -33.2278

Sheet carriers
A1: name | B1: color | C1: co2_emissions
A2: AC | B2: red
A3: coal | B3: black | C3: 0.3
A4: wind | B4: blue
A5: solar | B5: orange
A6: nuclear | B6: purple
A7: oil | B7: grey | C7: 0.15
A8: hydro | B8: pink
A9: loadshedding | B9: grey
A10: battery | B10: yellow
A11: gas | B11: blue | C11: 0.15

Sheet generators
A1: name | B1: bus | C1: carrier | D1: p_nom | E1: marginal_cost | F1: ramp_limit_up | G1: ramp_limit_down | H1: efficiency
A2: CFPP Mpumalanga | B2: EC | C2: coal | D2: 13272 | E2: 600 | F2: 0.045 | G2: 0.045 | H2: 0.3
A3: CFPP Free State | B3: FS | C3: coal | D3: 3708 | E3: 650 | F3: 0.016 | G3: 0.016 | H3: 0.33
A4: CFPP Limpopo | B4: LP | C4: coal | D4: 8310 | E4: 450 | F4: 0.07 | G4: 0.07 | H4: 0.35
A5: Solar Eastern Cape | B5: EC | C5: solar | D5: 100 | E5: 0
A6: Solar Free State | B6: FS | C6: solar | D6: 75 | E6: 0
A7: Solar Gauteng | B7: GP | C7: solar | D7: 100 | E7: 0
A8: Solar KwaZulu-Natal | B8: ZN | C8: solar | D8: 50 | E8: 0
A9: Solar Limpopo | B9: LP | C9: solar | D9: 50 | E9: 0
A10: Solar Mpumalanga | B10: MP | C10: solar | D10: 50 | E10: 0
A11: Solar North West | B11: NW | C11: solar | D11: 50 | E11: 0
A12: Solar Northern Cape | B12: NC | C12: solar | D12: 1500 | E12: 0
A13: Solar Western Cape | B13: WC | C13: solar | D13: 100 | E13: 0
A14: Wind Eastern Cape | B14: EC | C14: wind | D14: 700 | E14: 0
A15: Wind Free State | B15: FS | C15: wind | D15: 0 | E15: 0
A16: Wind Gauteng | B16: GP | C16: wind | D16: 0 | E16: 0
... A22: Wind Western Cape | B22: WC | C22: wind | D22: 100 | E22: 0
A23: OCGT Eastern Cape | B23: EC | C23: gas | D23: 2500 | E23: 1000 | H23: 0.25
A24: OCGT Western Cape | B24: WC | C24: gas | D24: 1300 | E24: 1001 | H24: 0.25
A25: CCGT KZN | B25: ZN | C25: gas | D25: 3000 | E25: 1002 | H25: 0.6

Sheet links
A1: name | B1: bus0 | C1: bus1 | D1: p_nom | E1: marginal_cost | F1: p_min_pu
A2: Eastern Cape to Free State | B2: EC | C2: FS | D2: 800 | E2: 0 | F2: -1
A3: Eastern Cape to KwaZulu-Natal | B3: EC | C3: ZN | D3: 800 | E3: 0 | F3: -1
A4: Eastern Cape to Northern Cape | B4: EC | C4: NC | D4: 1800 | E4: 0 | F4: -1
A5: Eastern Cape to Western Cape | B5: EC | C5: WC | D5: 5000 | E5: 0 | F5: -1
A6: Free State to Gauteng | B6: FS | C6: GP | D6: 3500 | E6: 0 | F6: -1
A7: Free State to KwaZulu-Natal | B7: FS | C7: ZN | D7: 3000 | E7: 0 | F7: -1
A8: Free State to Mpumalanga | B8: FS | C8: MP | D8: 1000 | E8: 0 | F8: -1
A9: Free State to North West | B9: FS | C9: NW | D9: 1000 | E9: 0 | F9: -1
A10: Free State to Northern Cape | B10: FS | C10: NC | D10: 5000 | E10: 0 | F10: -1
A11: Gauteng to Limpopo | B11: GP | C11: LP | D11: 12000 | E11: 0 | F11: -1
A12: Gauteng to Mpumalanga | B12: GP | C12: MP | D12: 12000 | E12: 0 | F12: -1
A13: Gauteng to North West | B13: GP | C13: NW | D13: 5000 | E13: 0 | F13: -1
... A19: Northern Cape to Western Cape | B19: NC | C19: WC | D19: 3000 | E19: 0 | F19: -1

Sheet loads
A1: name | B1: bus | C1: carrier
A2: Eastern Cape Load | B2: EC | C2: AC
A3: Free State Load | B3: FS | C3: AC
A4: Gauteng Load | B4: GP | C4: AC
A5: KwaZulu Natal Load | B5: ZN | C5: AC
A6: Limpopo Load | B6: LP | C6: AC
A7: Mpumalanga Load | B7: MP | C7: AC
A8: North West Load | B8: NW | C8: AC
A9: Northern Cape Load | B9: NC | C9: AC
A10: Western Cape Load | B10: WC | C10: AC

Sheet storage_units
A1: name | B1: bus | C1: carrier | D1: p_nom | E1: max_hours | F1: efficiency_store | G1: efficiency_dispatch
A2: Ingula | B2: ZN | C2: hydro | D2: 1332 | E2: 16 | F2: 0.88 | G2: 0.88
A3: Drakensberg | B3: ZN | C3: hydro | D3: 1000 | E3: 28 | F3: 0.88 | G3: 0.88
A4: Palmiet | B4: WC | C4: hydro | D4: 400 | E4: 14 | F4: 0.88 | G4: 0.88
A5: Steenbras | B5: WC | C5: hydro | D5: 180 | E5: 30 | F5: 0.88 | G5: 0.88
A6: ="BESS "&B6 -> BESS EC | B6: =buses!A2 -> EC | C6: battery | D6: 0 | E6: 4 | F6: 0.95 | G6: 0.95
A7: ="BESS "&B7 -> BESS FS | B7: =buses!A3 -> FS | C7: battery | D7: 0 | E7: 4 | F7: 0.95 | G7: 0.95
A8: ="BESS "&B8 -> BESS GP | B8: =buses!A4 -> GP | C8: battery | D8: 0 | E8: 4 | F8: 0.95 | G8: 0.95
A9: ="BESS "&B9 -> BESS ZN | B9: =buses!A5 -> ZN | C9: battery | D9: 0 | E9: 4 | F9: 0.95 | G9: 0.95
A10: ="BESS "&B10 -> BESS LP | B10: =buses!A6 -> LP | C10: battery | D10: 0 | E10: 4 | F10: 0.95 | G10: 0.95
A11: ="BESS "&B11 -> BESS MP | B11: =buses!A7 -> MP | C11: battery | D11: 0 | E11: 4 | F11: 0.95 | G11: 0.95
A12: ="BESS "&B12 -> BESS NW | B12: =buses!A8 -> NW | C12: battery | D12: 0 | E12: 4 | F12: 0.95 | G12: 0.95
A13: ="BESS "&B13 -> BESS NC | B13: =buses!A9 -> NC | C13: battery | D13: 0 | E13: 4 | F13: 0.95 | G13: 0.95
A14: ="BESS "&B14 -> BESS WC | B14: =buses!A10 -> WC | C14: battery | D14: 0 | E14: 4 | F14: 0.95 | G14: 0.95

Sheet snapshots
A1: time
A2: 45292
A3: =A2+1/24 -> 45292.042
A4: =A3+1/24 -> 45292.083
A5: =A4+1/24 -> 45292.125
A6: =A5+1/24 -> 45292.167
A7: =A6+1/24 -> 45292.208
A8: =A7+1/24 -> 45292.25
A9: =A8+1/24 -> 45292.292
A10: =A9+1/24 -> 45292.333
A11: =A10+1/24 -> 45292.375
A12: =A11+1/24 -> 45292.417
A13: =A12+1/24 -> 45292.458
A14: =A13+1/24 -> 45292.5
... A8761: =A8760+1/24 -> 45656.958

Sheet generators-p_max_pu
A1: time | B1: Solar Eastern Cape | C1: Wind Eastern Cape | D1: Solar Free State | E1: Wind Free State | F1: Solar Gauteng | G1: Wind Gauteng | H1: Solar Limpopo | I1: Wind Limpopo | J1: Solar Mpumalanga | K1: Wind Mpumalanga | L1: Solar Northern Cape | M1: Wind Northern Cape | N1: Solar North West | O1: Wind North West | P1: Solar Western Cape | Q1: Wind Western Cape | R1: Solar KwaZulu-Natal | S1: Wind KwaZulu-Natal
A2: 45292 | B2: 0 | C2: 0.42 | D2: 0 | E2: 0.565 | F2: 0 | G2: 0.186 | H2: 0 | I2: 0.513 | J2: 0 | K2: 0.379 | L2: 0 | M2: 0.696 | N2: 0 | O2: 0.068 | P2: 0 | Q2: 0.603 | R2: 0 | S2: 0.028
A3: =A2+1/24 -> 45292.042 | B3: 0 | C3: 0.4 | D3: 0 | E3: 0.506 | F3: 0 | G3: 0.251 | H3: 0 | I3: 0.457 | J3: 0 | K3: 0.305 | L3: 0 | M3: 0.677 | N3: 0 | O3: 0.119 | P3: 0 | Q3: 0.54 | R3: 0 | S3: 0.015
A4: =A3+1/24 -> 45292.083 | B4: 0 | C4: 0.241 | D4: 0 | E4: 0.257 | F4: 0 | G4: 0.042 | H4: 0 | I4: 0.343 | J4: 0 | K4: 0.155 | L4: 0 | M4: 0.481 | N4: 0 | O4: 0.124 | P4: 0 | Q4: 0.123 | R4: 0 | S4: 0.494
A5: =A4+1/24 -> 45292.125 | B5: 0 | C5: 0.129 | D5: 0 | E5: 0.148 | F5: 0 | G5: 0.097 | H5: 0 | I5: 0.405 | J5: 0 | K5: 0.223 | L5: 0 | M5: 0.349 | N5: 0 | O5: 0.144 | P5: 0 | Q5: 0.111 | R5: 0 | S5: 0.507
A6: =A5+1/24 -> 45292.167 | B6: 0 | C6: 0.076 | D6: 0 | E6: 0.095 | F6: 0 | G6: 0.154 | H6: 0 | I6: 0.445 | J6: 0 | K6: 0.283 | L6: 0 | M6: 0.241 | N6: 0 | O6: 0.141 | P6: 0 | Q6: 0.1 | R6: 0 | S6: 0.519
A7: =A6+1/24 -> 45292.208 | B7: 0.013 | C7: 0.227 | D7: 0.006 | E7: 0.094 | F7: 0.001 | G7: 0.165 | H7: 0.006 | I7: 0.407 | J7: 0.004 | K7: 0.285 | L7: 0 | M7: 0.192 | N7: 0 | O7: 0.114 | P7: 0 | Q7: 0.063 | R7: 0.019 | S7: 0.441
A8: =A7+1/24 -> 45292.25 | B8: 0.087 | C8: 0.524 | D8: 0.055 | E8: 0.09 | F8: 0.028 | G8: 0.114 | H8: 0.087 | I8: 0.49 | J8: 0.067 | K8: 0.192 | L8: 0.037 | M8: 0.307 | N8: 0.034 | O8: 0.069 | P8: 0.038 | Q8: 0.02 | R8: 0.1 | S8: 0.332
A9: =A8+1/24 -> 45292.292 | B9: 0.226 | C9: 0.753 | D9: 0.235 | E9: 0.074 | F9: 0.082 | G9: 0.065 | H9: 0.249 | I9: 0.476 | J9: 0.179 | K9: 0.118 | L9: 0.159 | M9: 0.399 | N9: 0.104 | O9: 0.064 | P9: 0.161 | Q9: 0.017 | R9: 0.213 | S9: 0.281
A10: =A9+1/24 -> 45292.333 | B10: 0.387 | C10: 0.748 | D10: 0.426 | E10: 0.065 | F10: 0.16 | G10: 0.053 | H10: 0.422 | I10: 0.446 | J10: 0.253 | K10: 0.047 | L10: 0.347 | M10: 0.264 | N10: 0.186 | O10: 0.076 | P10: 0.374 | Q10: 0.045 | R10: 0.303 | S10: 0.21
A11: =A10+1/24 -> 45292.375 | B11: 0.511 | C11: 0.661 | D11: 0.568 | E11: 0.058 | F11: 0.221 | G11: 0.037 | H11: 0.556 | I11: 0.366 | J11: 0.278 | K11: 0.006 | L11: 0.509 | M11: 0.132 | N11: 0.248 | O11: 0.068 | P11: 0.553 | Q11: 0.116 | R11: 0.367 | S11: 0.133
A12: =A11+1/24 -> 45292.417 | B12: 0.595 | C12: 0.523 | D12: 0.657 | E12: 0.048 | F12: 0.279 | G12: 0.024 | H12: 0.603 | I12: 0.281 | J12: 0.267 | K12: 0.004 | L12: 0.619 | M12: 0.058 | N12: 0.264 | O12: 0.05 | P12: 0.653 | Q12: 0.22 | R12: 0.415 | S12: 0.096
A13: =A12+1/24 -> 45292.458 | B13: 0.669 | C13: 0.538 | D13: 0.705 | E13: 0.03 | F13: 0.35 | G13: 0.017 | H13: 0.542 | I13: 0.203 | J13: 0.276 | K13: 0.011 | L13: 0.684 | M13: 0.025 | N13: 0.262 | O13: 0.041 | P13: 0.733 | Q13: 0.294 | R13: 0.405 | S13: 0.101
A14: =A13+1/24 -> 45292.5 | B14: 0.71 | C14: 0.734 | D14: 0.709 | E14: 0.015 | F14: 0.356 | G14: 0.017 | H14: 0.468 | I14: 0.119 | J14: 0.317 | K14: 0.012 | L14: 0.707 | M14: 0.011 | N14: 0.232 | O14: 0.048 | P14: 0.762 | Q14: 0.307 | R14: 0.374 | S14: 0.167
... A8761: =A8760+1/24 -> 45656.958 | B8761: 0 | C8761: 0.39 | D8761: 0 | E8761: 0.555 | F8761: 0 | G8761: 0.078 | H8761: 0 | I8761: 0.599 | J8761: 0 | K8761: 0.402 | L8761: 0 | M8761: 0.627 | N8761: 0 | O8761: 0.043 | P8761: 0 | Q8761: 0.644 | R8761: 0 | S8761: 0.042

Sheet loads-p_set
A1: time | B1: Eastern Cape Load | C1: Limpopo Load | D1: Mpumalanga Load | E1: Gauteng Load | F1: Western Cape Load | G1: KwaZulu Natal Load | H1: North West Load | I1: Free State Load | J1: Northern Cape Load
A2: 45292 | B2: 993.41872 | C2: 2405.9127 | D2: 2909.7878 | E2: 5614.0673 | F2: 2165.6847 | G2: 4351.4566 | H2: 2482.4523 | I2: 624.10872 | J2: 793.76016
A3: =A2+1/24 -> 45292.042 | B3: 984.26172 | C3: 2414.9752 | D3: 3004.4124 | E3: 5538.5746 | F3: 2097.919 | G3: 4331.4475 | H3: 2477.941 | I3: 605.84145 | J3: 752.86354
A4: =A3+1/24 -> 45292.083 | B4: 959.21261 | C4: 2371.7102 | D4: 3043.7004 | E4: 5485.3338 | F4: 2031.7807 | G4: 4260.6477 | H4: 2488.1272 | I4: 598.61474 | J4: 728.49742
A5: =A4+1/24 -> 45292.125 | B5: 950.02328 | C5: 2305.9203 | D5: 3071.7531 | E5: 5523.3747 | F5: 2018.976 | G5: 4312.5809 | H5: 2486.3794 | I5: 599.64883 | J5: 747.3468
A6: =A5+1/24 -> 45292.167 | B6: 1016.8604 | C6: 2380.1369 | D6: 3223.4566 | E6: 5819.7871 | F6: 2153.8448 | G6: 4527.0662 | H6: 2492.2758 | I6: 628.40284 | J6: 774.50073
A7: =A6+1/24 -> 45292.208 | B7: 1148.2658 | C7: 2561.4468 | D7: 3425.9641 | E7: 6320.0791 | F7: 2362.2044 | G7: 5017.1811 | H7: 2695.2074 | I7: 668.3676 | J7: 803.22376
A8: =A7+1/24 -> 45292.25 | B8: 1305.1844 | C8: 2629.875 | D8: 3490.6244 | E8: 6764.4795 | F8: 2530.852 | G8: 5386.1651 | H8: 2812.3636 | I8: 721.34764 | J8: 819.59528
A9: =A8+1/24 -> 45292.292 | B9: 1394.3468 | C9: 2627.6309 | D9: 3413.8509 | E9: 6978.5693 | F9: 2656.1532 | G9: 5531.1746 | H9: 2733.0963 | I9: 752.69705 | J9: 815.81275
A10: =A9+1/24 -> 45292.333 | B10: 1528.9668 | C10: 2821.218 | D10: 3618.2368 | E10: 7393.1241 | F10: 2816.9467 | G10: 5861.8935 | H10: 2756.5288 | I10: 789.60361 | J10: 821.43753
A11: =A10+1/24 -> 45292.375 | B11: 1560.9916 | C11: 2955.3254 | D11: 3773.1736 | E11: 7627.7611 | F11: 2976.7831 | G11: 5973.5945 | H11: 2750.4699 | I11: 793.82314 | J11: 768.73752
A12: =A11+1/24 -> 45292.417 | B12: 1537.9179 | C12: 2996.9337 | D12: 3771.444 | E12: 7672.8567 | F12: 3037.7824 | G12: 5905.0643 | H12: 2720.4713 | I12: 786.25931 | J12: 753.37381
A13: =A12+1/24 -> 45292.458 | B13: 1492.1666 | C13: 2944.9301 | D13: 3721.3399 | E13: 7465.4937 | F13: 2971.8007 | G13: 5686.0554 | H13: 2701.8803 | I13: 776.02848 | J13: 770.05827
A14: =A13+1/24 -> 45292.5 | B14: 1477.153 | C14: 2937.0353 | D14: 3693.8854 | E14: 7391.1537 | F14: 2963.0744 | G14: 5668.7813 | H14: 2738.6061 | I14: 772.70225 | J14: 762.51085
... A8761: =A8760+1/24 -> 45656.958 | B8761: 992.751 | C8761: 2377.5633 | D8761: 3001.5451 | E8761: 5474.3352 | F8761: 2233.2145 | G8761: 4191.0757 | H8761: 2383.0618 | I8761: 621.72232 | J8761: 775.74895

Sheet var-links
A1: attribute | B1: type | C1: unit | D1: default | E1: description | F1: status
A2: name | B2: string | E2: Unique name | F2: Input (required)
A3: bus0 | B3: string | E3: Name of first bus to which link is attached. | F3: Input (required)
A4: bus1 | B4: string | E4: Name of other bus to which link is attached. | F4: Input (required)
A5: type | B5: string | E5: Placeholder for link type. Not yet implemented. | F5: Input (optional)
A6: carrier | B6: string | E6: Energy carrier transported by the link: can be "DC" for electrical HVDC links, or "heat" or "gas" etc. | F6: Input (optional)
A7: efficiency | B7: static or series | C7: per unit | D7: 1 | E7: Efficiency of power transfer from bus0 to bus1. (Can be time-dependent to represent temperature-dependent Coefficient of Performance of a heat pump from an electric to a heat bus.) | F7: Input (optional)
A8: build_year | B8: int | C8: year | D8: 0 | E8: build year | F8: Input (optional)
A9: lifetime | B9: float | C9: years | D9: inf | E9: lifetime | F9: Input (optional)
A10: p_nom | B10: float | C10: MW | D10: 0 | E10: Limit of active power which can pass through link. | F10: Input (optional)
A11: p_nom_mod | B11: float | C11: MW | D11: 0 | E11: Limit of active power of the link module. | F11: Input (optional)
A12: p_nom_extendable | B12: boolean | D12: False | E12: Switch to allow capacity p_nom to be extended. | F12: Input (optional)
A13: p_nom_min | B13: float | C13: MW | D13: 0 | E13: If p_nom is extendable, set its minimum value. | F13: Input (optional)
A14: p_nom_max | B14: float | C14: MW | D14: inf | E14: If p_nom is extendable, set its maximum value (e.g. limited by potential). | F14: Input (optional)
A15: p_set | B15: static or series | C15: MW | D15: 0 | E15: The dispatch set point for p0 of the link in PF. | F15: Input (optional)
A16: p_min_pu | B16: static or series | C16: per unit of p_nom | D16: 0. | E16: Minimal dispatch (can also be negative) per unit of p_nom for the link. | F16: Input (optional)
A17: p_max_pu | B17: static or series | C17: per unit of p_nom | D17: 1. | E17: Maximal dispatch (can also be negative) per unit of p_nom for the link. | F17: Input (optional)
A18: capital_cost | B18: float | C18: currency/MW | D18: 0 | E18: Fixed period costs of extending p_nom by 1 MW, including periodized investment costs and periodic fixed O&M costs (e.g. annuitized investment costs). | F18: Input (optional)
A19: marginal_cost | B19: static or series | C19: currency/MWh | D19: 0. | E19: Marginal cost of transfering 1 MWh (before efficiency losses) from bus0 to bus1. NB: marginal cost only makes sense if p_max_pu >= 0. | F19: Input (optional)
A20: marginal_cost_quadratic | B20: static or series | C20: currency/MWh | D20: 0. | E20: Quadratic marginal cost for transferring 1 MWh (before efficiency losses) from bus0 to bus1. | F20: Input (optional)
A21: stand_by_cost | B21: static or series | C21: currency/h | D21: 0. | E21: Stand-by cost for operating the link at null power flow. | F21: Input (optional)
A22: length | B22: float | C22: km | D22: 0 | E22: Length of line, useful for calculating the capital cost. | F22: Input (optional)
A23: terrain_factor | B23: float | C23: per unit | D23: 1 | E23: Terrain factor for increasing capital cost. | F23: Input (optional)
A24: committable | B24: boolean | D24: False | E24: Use unit commitment (only possible if p_nom is not extendable). | F24: Input (optional)
A25: start_up_cost | B25: float | C25: currency | D25: 0 | E25: Cost to start up the link. Only read if committable is True. | F25: Input (optional)
A26: shut_down_cost | B26: float | C26: currency | D26: 0 | E26: Cost to shut down the link. Only read if committable is True. | F26: Input (optional)
A27: min_up_time | B27: int | C27: snapshots | D27: 0 | E27: Minimum number of snapshots for status to be 1. Only read if committable is True. | F27: Input (optional)
A28: min_down_time | B28: int | C28: snapshots | D28: 0 | E28: Minimum number of snapshots for status to be 0. Only read if committable is True. | F28: Input (optional)
A29: up_time_before | B29: int | C29: snapshots | D29: 1 | E29: Number of snapshots that the link was online before network.snapshots start. Only read if committable is True and min_up_time is non-zero. | F29: Input (optional)
A30: down_time_before | B30: int | C30: snapshots | D30: 0 | E30: Number of snapshots that the link was offline before network.snapshots start. Only read if committable is True and min_down_time is non-zero. | F30: Input (optional)
A31: ramp_limit_up | B31: static or series | C31: per unit | E31: Maximum increase from one snapshot to the next, per unit of the bus0 unit. Ignored if NaN. | F31: Input (optional)
A32: ramp_limit_down | B32: static or series | C32: per unit | E32: Maximum decrease from one snapshot to the next, per unit of the bus0 unit. Ignored if NaN. | F32: Input (optional)
A33: ramp_limit_start_up | B33: float | C33: per unit | D33: 1 | E33: Maximumincrease at start up, per unit of bus0 unit. Only read if committable is True. | F33: Input (optional)
A34: ramp_limit_shut_down | B34: float | C34: per unit | D34: 1 | E34: Maximum decrease at shut down, per unit of bus0 unit. Only read if committable is True. | F34: Input (optional)
A35: bus2 | B35: string | E35: Name of other bus to which link is attached. | F35: Input (required)
A36: bus3 | B36: string | E36: Name of other bus to which link is attached. | F36: Input (required)
A37: efficiency2 | B37: static or series | C37: per unit | D37: 1 | E37: Efficiency of power transfer from bus0 to bus1. (Can be time-dependent to represent temperature-dependent Coefficient of Performance of a heat pump from an electric to a heat bus.) | F37: Input (optional)
A38: efficiency3 | B38: static or series | C38: per unit | D38: 1 | E38: Efficiency of power transfer from bus0 to bus1. (Can be time-dependent to represent temperature-dependent Coefficient of Performance of a heat pump from an electric to a heat bus.) | F38: Input (optional)
A39: p0 | B39: series | C39: MW | D39: 0. | E39: Active power at bus0 (positive if branch is withdrawing power from bus0). | F39: Output
A40: p1 | B40: series | C40: MW | D40: 0. | E40: Active power at bus1 (positive if branch is withdrawing power from bus1). | F40: Output
...

Sheet var-storage_units
A1: attribute | B1: type | C1: unit | D1: default | E1: description | F1: status
A2: name | B2: string | E2: Unique name | F2: Input (required)
A3: bus | B3: string | E3: Name of bus to which storage unit is attached. | F3: Input (required)
A4: control | B4: string | D4: PQ | E4: P,Q,V control strategy for PF, must be "PQ", "PV" or "Slack". | F4: Input (optional)
A5: type | B5: string | E5: Placeholder for storage unit type. Not yet implemented. | F5: Input (optional)
A6: p_nom | B6: float | C6: MW | D6: 0 | E6: Nominal power for limits in OPF. | F6: Input (optional)
A7: p_nom_mod | B7: float | C7: MW | D7: 0 | E7: Nominal power of the storage unit module. | F7: Input (optional)
A8: p_nom_extendable | B8: boolean | D8: False | E8: Switch to allow capacity p_nom to be extended in OPF. | F8: Input (optional)
A9: p_nom_min | B9: float | C9: MW | D9: 0 | E9: If p_nom is extendable in OPF, set its minimum value. | F9: Input (optional)
A10: p_nom_max | B10: float | C10: MW | D10: inf | E10: If p_nom is extendable in OPF, set its maximum value (e.g. limited by potential). | F10: Input (optional)
A11: p_min_pu | B11: static or series | C11: per unit | D11: -1 | E11: The minimum output for each snapshot per unit of p_nom for the OPF (negative sign implies storing mode withdrawing power from bus). | F11: Input (optional)
A12: p_max_pu | B12: static or series | C12: per unit | D12: 1 | E12: The maximum output for each snapshot per unit of p_nom for the OPF. | F12: Input (optional)
A13: p_set | B13: static or series | C13: MW | D13: 0 | E13: active power set point (for PF) | F13: Input (optional)
A14: q_set | B14: static or series | C14: MVar | D14: 0 | E14: reactive power set point (for PF) | F14: Input (optional)
A15: sign | B15: float | D15: 1 | E15: power sign | F15: Input (optional)
A16: carrier | B16: string | E16: Prime mover energy carrier (e.g. coal, gas, wind, solar); required for global constraints on primary energy in OPF | F16: Input (optional)
A17: marginal_cost | B17: static or series | C17: currency/MWh | D17: 0 | E17: Marginal cost of production of 1 MWh. | F17: Input (optional)
A18: marginal_cost_quadratic | B18: static or series | C18: currency/MWh | D18: 0 | E18: Quadratic marginal cost of production (discharge) of 1 MWh. | F18: Input (optional)
A19: capital_cost | B19: float | C19: currency/MW | D19: 0 | E19: Fixed period costs of extending p_nom by 1 MW, including periodized investment costs and periodic fixed O&M costs (e.g. annuitized investment costs). | F19: Input (optional)
A20: build_year | B20: int | C20: year | D20: 0 | E20: build year | F20: Input (optional)
A21: lifetime | B21: float | C21: years | D21: inf | E21: lifetime | F21: Input (optional)
A22: state_of_charge_initial | B22: float | C22: MWh | D22: 0 | E22: State of charge before the snapshots in the OPF. | F22: Input (optional)
A23: state_of_charge_initial_per_period | B23: boolean | D23: False | E23: Switch: if True, then state of charge at the beginning of an investment period is set to state_of_charge_initial | F23: Input (optional)
A24: state_of_charge_set | B24: static or series | C24: MWh | E24: State of charge set points for snapshots in the OPF. | F24: Input (optional)
A25: cyclic_state_of_charge | B25: boolean | D25: False | E25: Switch: if True, then state_of_charge_initial is ignored and the initial state of charge is set to the final state of charge for the group of snapshots in the OPF (soc[-1] = soc[len(snapshots)-1]). | F25: Input (optional)
A26: cyclic_state_of_charge_per_period | B26: boolean | D26: True | E26: Switch: if True, then the cyclic constraints are applied to each period (first snapshot level if multiindexed) separately. | F26: Input (optional)
A27: max_hours | B27: float | C27: hours | D27: 1 | E27: Maximum state of charge capacity in terms of hours at full output capacity p_nom | F27: Input (optional)
A28: efficiency_store | B28: static or series | C28: per unit | D28: 1 | E28: Efficiency of storage on the way into the storage. | F28: Input (optional)
A29: efficiency_dispatch | B29: static or series | C29: per unit | D29: 1 | E29: Efficiency of storage on the way out of the storage. | F29: Input (optional)
A30: standing_loss | B30: static or series | C30: per unit | D30: 0 | E30: Losses per hour to state of charge. | F30: Input (optional)
A31: inflow | B31: static or series | C31: MW | D31: 0 | E31: Inflow to the state of charge, e.g. due to river inflow in hydro reservoir. | F31: Input (optional)
A32: p | B32: series | C32: MW | D32: 0 | E32: active power at bus (positive if net generation) | F32: Output
A33: p_dispatch | B33: series | C33: MW | D33: 0 | E33: active power dispatch at bus | F33: Output
A34: p_store | B34: series | C34: MW | D34: 0 | E34: active power charging at bus | F34: Output
A35: q | B35: series | C35: MVar | D35: 0 | E35: reactive power (positive if net generation) | F35: Output
A36: state_of_charge | B36: series | C36: MWh | E36: State of charge as calculated by the OPF. | F36: Output
A37: spill | B37: series | C37: MW | D37: 0 | E37: Spillage for each snapshot. | F37: Output
A38: p_nom_opt | B38: float | C38: MW | D38: 0 | E38: Optimised nominal power. | F38: Output
A39: mu_upper | B39: series | C39: currency/MWh | D39: 0 | E39: Shadow price of upper p_nom limit | F39: Output
A40: mu_lower | B40: series | C40: currency/MWh | D40: 0 | E40: Shadow price of lower p_nom limit | F40: Output
...

Sheet var-buses
A1: attribute | B1: type | C1: unit | D1: default | E1: description | F1: status
A2: name | B2: string | E2: Unique name | F2: Input (required)
A3: v_nom | B3: float | C3: kV | D3: 1 | E3: Nominal voltage | F3: Input (optional)
A4: type | B4: string | E4: Placeholder for bus type. Not yet implemented. | F4: Input (optional)
A5: x | B5: float | D5: 0 | E5: Position (e.g. longitude); the Spatial Reference System Identifier (SRID) is set in network.srid. | F5: Input (optional)
A6: y | B6: float | D6: 0 | E6: Position (e.g. latitude); the Spatial Reference System Identifier (SRID) is set in network.srid. | F6: Input (optional)
A7: carrier | B7: string | D7: AC | E7: Energy carrier: can be "AC" or "DC" for electrical buses, or "heat" or "gas". | F7: Input (optional)
A8: unit | B8: string | E8: Unit of the bus’ carrier if the implicitly assumed unit ("MW") is inappropriate (e.g. "t/h", "MWh_th/h"). Only descriptive. Does not influence any PyPSA functions. | F8: Input (optional)
A9: v_mag_pu_set | B9: static or series | C9: per unit | D9: 1 | E9: Voltage magnitude set point, per unit of v_nom. | F9: Input (optional)
A10: v_mag_pu_min | B10: float | C10: per unit | D10: 0 | E10: Minimum desired voltage, per unit of v_nom. This is a placeholder attribute and is not currently used by any PyPSA functions. | F10: Input (optional)
A11: v_mag_pu_max | B11: float | C11: per unit | D11: inf | E11: Maximum desired voltage, per unit of v_nom. This is a placeholder attribute and is not currently used by any PyPSA functions. | F11: Input (optional)
A12: control | B12: string | D12: PQ | E12: P,Q,V control strategy for PF, must be "PQ", "PV" or "Slack". Note that this attribute is an output inherited from the controls of the generators attached to the bus; setting it directly on the bus will not have any effect. | F12: Output
A13: generator | B13: string | E13: Name of slack generator attached to slack bus. | F13: Output
A14: sub_network | B14: string | E14: Name of connected sub-network to which bus belongs. This attribute is set by PyPSA in the function network.determine_network_topology(); do not set it directly by hand. | F14: Output
A15: p | B15: series | C15: MW | D15: 0. | E15: active power at bus (positive if net generation at bus) | F15: Output
A16: q | B16: series | C16: MVar | D16: 0. | E16: reactive power (positive if net generation at bus) | F16: Output
A17: v_mag_pu | B17: series | C17: per unit | D17: 1. | E17: Voltage magnitude, per unit of v_nom | F17: Output
A18: v_ang | B18: series | C18: radians | D18: 0. | E18: Voltage angle | F18: Output
A19: marginal_price | B19: series | C19: currency/MWh | D19: 0. | E19: Locational marginal price from LOPF from power balance constraint | F19: Output

Sheet var-carriers
A1: attribute | B1: type | C1: unit | D1: default | E1: description | F1: status
A2: name | B2: string | E2: Unique name | F2: Input (required)
A3: co2_emissions | B3: float | C3: tonnes/MWh | D3: 0 | E3: Emissions in CO2-tonnes-equivalent per MWh of primary energy (e.g. methane has 0.2 tonnes_CO2/MWh_thermal). | F3: Input (optional)
A4: color | B4: string | E4: plotting color | F4: Input (optional)
A5: nice_name | B5: string | E5: More precise descriptive name | F5: Input (optional)
A6: max_growth | B6: float | C6: MW | D6: inf | E6: maximum new installed capacity per investment period | F6: Input (optional)
A7: max_relative_growth | B7: float | C7: MW | D7: 0 | E7: maximum capacity ratio for new installed capacity per investment period (in addition to max_growth) | F7: Input (optional)

Sheet var-generators
A1: attribute | B1: type | C1: unit | D1: default | E1: description | F1: status
A2: name | B2: string | E2: Unique name | F2: Input (required)
A3: bus | B3: string | E3: name of bus to which generator is attached | F3: Input (required)
A4: control | B4: string | D4: PQ | E4: P,Q,V control strategy for PF, must be "PQ", "PV" or "Slack". | F4: Input (optional)
A5: type | B5: string | E5: Placeholder for generator type. Not yet implemented. | F5: Input (optional)
A6: p_nom | B6: float | C6: MW | D6: 0 | E6: Nominal power for limits in optimization. | F6: Input (optional)
A7: p_nom_mod | B7: float | C7: MW | D7: 0 | E7: Nominal power of the generator module. | F7: Input (optional)
A8: p_nom_extendable | B8: boolean | D8: False | E8: Switch to allow capacity p_nom to be extended in optimization. | F8: Input (optional)
A9: p_nom_min | B9: float | C9: MW | D9: 0 | E9: If p_nom is extendable in optimization, set its minimum value. | F9: Input (optional)
A10: p_nom_max | B10: float | C10: MW | D10: inf | E10: If p_nom is extendable in optimization, set its maximum value (e.g. limited by technical potential). | F10: Input (optional)
A11: p_min_pu | B11: static or series | C11: per unit | D11: 0. | E11: The minimum output for each snapshot per unit of p_nom for the optimization (e.g. for variable renewable generators this can change due to weather conditions and compulsory feed-in; for conventional generators it represents a minimal dispatch). Note that if comittable is False and p_min_pu > 0, this represents a must-run condition. | F11: Input (optional)
A12: p_max_pu | B12: static or series | C12: per unit | D12: 1 | E12: The maximum output for each snapshot per unit of p_nom for the optimization (e.g. for variable renewable generators this can change due to weather conditions; for conventional generators it represents a maximum dispatch). | F12: Input (optional)
A13: p_set | B13: static or series | C13: MW | D13: 0. | E13: active power set point (for PF) | F13: Input (optional)
A14: q_set | B14: static or series | C14: MVar | D14: 0. | E14: reactive power set point (for PF) | F14: Input (optional)
A15: sign | B15: float | D15: 1 | E15: power sign | F15: Input (optional)
A16: carrier | B16: string | E16: Prime mover energy carrier (e.g. coal, gas, wind, solar); required for global constraints on primary energy in optimization | F16: Input (optional)
A17: marginal_cost | B17: static or series | C17: currency/MWh | D17: 0. | E17: Marginal cost of production of 1 MWh. | F17: Input (optional)
A18: marginal_cost_quadratic | B18: static or series | C18: currency/MWh | D18: 0. | E18: Quadratic marginal cost of production of 1 MWh. | F18: Input (optional)
A19: build_year | B19: int | C19: year | D19: 0 | E19: build year | F19: Input (optional)
A20: lifetime | B20: float | C20: years | D20: inf | E20: lifetime | F20: Input (optional)
A21: capital_cost | B21: float | C21: currency/MW | D21: 0 | E21: Fixed period costs of extending p_nom by 1 MW, including periodized investment costs and periodic fixed O&M costs (e.g. annuitized investment costs). | F21: Input (optional)
A22: efficiency | B22: static or series | C22: per unit | D22: 1 | E22: Ratio between primary energy and electrical energy, e.g. takes value 0.4 MWh_elec/MWh_thermal for gas. This is required for global constraints on primary energy in optimization. | F22: Input (optional)
A23: committable | B23: boolean | D23: False | E23: Use unit commitment (only possible if p_nom is not extendable). | F23: Input (optional)
A24: start_up_cost | B24: float | C24: currency | D24: 0 | E24: Cost to start up the generator. Only read if committable is True. | F24: Input (optional)
A25: shut_down_cost | B25: float | C25: currency | D25: 0 | E25: Cost to shut down the generator. Only read if committable is True. | F25: Input (optional)
A26: stand_by_cost | B26: static or series | C26: currency/h | D26: 0. | E26: Stand-by cost for operating the generator at null power output. | F26: Input (optional)
A27: min_up_time | B27: int | C27: snapshots | D27: 0 | E27: Minimum number of snapshots for status to be 1. Only read if committable is True. | F27: Input (optional)
A28: min_down_time | B28: int | C28: snapshots | D28: 0 | E28: Minimum number of snapshots for status to be 0. Only read if committable is True. | F28: Input (optional)
A29: up_time_before | B29: int | C29: snapshots | D29: 1 | E29: Number of snapshots that the generator was online before network.snapshots start. Only read if committable is True and min_up_time is non-zero. | F29: Input (optional)
A30: down_time_before | B30: int | C30: snapshots | D30: 0 | E30: Number of snapshots that the generator was offline before network.snapshots start. Only read if committable is True and min_down_time is non-zero. | F30: Input (optional)
A31: ramp_limit_up | B31: static or series | C31: per unit | E31: Maximum active power increase from one snapshot to the next, per unit of the nominal power. Ignored if NaN. | F31: Input (optional)
A32: ramp_limit_down | B32: static or series | C32: per unit | E32: Maximum active power decrease from one snapshot to the next, per unit of the nominal power. Ignored if NaN. | F32: Input (optional)
A33: ramp_limit_start_up | B33: float | C33: per unit | D33: 1 | E33: Maximum active power increase at start up, per unit of the nominal power. Only read if committable is True. | F33: Input (optional)
A34: ramp_limit_shut_down | B34: float | C34: per unit | D34: 1 | E34: Maximum active power decrease at shut down, per unit of the nominal power. Only read if committable is True. | F34: Input (optional)
A35: weight | B35: float | D35: 1 | E35: Weighting of a generator. Only used for network clustering. | F35: Input (optional)
A36: p | B36: series | C36: MW | D36: 0. | E36: active power at bus (positive if net generation) | F36: Output
A37: q | B37: series | C37: MVar | D37: 0. | E37: reactive power (positive if net generation) | F37: Output
A38: p_nom_opt | B38: float | C38: MW | D38: 0. | E38: Optimised nominal power. | F38: Output
A39: status | B39: series | D39: 1 | E39: Status (1 is on, 0 is off). Only outputted if committable is True. | F39: Output
A40: mu_upper | B40: series | C40: currency/MWh | D40: 0. | E40: Shadow price of upper p_nom limit | F40: Output
...

Sheet var-loads
A1: attribute | B1: type | C1: unit | D1: default | E1: description | F1: status
A2: name | B2: string | E2: Unique name | F2: Input (required)
A3: bus | B3: string | E3: Name of bus to which load is attached. | F3: Input (required)
A4: carrier | B4: string | E4: Energy carrier: can be "AC" or "DC" for electrical buses, or "heat" or "gas". | F4: Input (optional)
A5: type | B5: string | E5: Placeholder for load type. Not yet implemented. | F5: Input (optional)
A6: p_set | B6: static or series | C6: MW | D6: 0 | E6: Active power consumption (positive if the load is consuming power). | F6: Input (optional)
A7: q_set | B7: static or series | C7: MVar | D7: 0 | E7: Reactive power consumption (positive if the load is inductive). | F7: Input (optional)
A8: sign | B8: float | D8: -1 | E8: power sign (opposite sign to generator) | F8: Input (optional)
A9: p | B9: series | C9: MW | D9: 0 | E9: active power at bus (positive if net load) | F9: Output
A10: q | B10: series | C10: MVar | D10: 0 | E10: reactive power (positive if net load) | F10: Output

Sheet var-networks
A1: attribute | B1: type | C1: unit | D1: default | E1: description | F1: status
A2: name | B2: string | E2: Unique name | F2: Input (required)
A3: snapshots | B3: list or pandas.Index | D3: ["now"] | E3: List of snapshots or time steps. All time-dependent series quantities are indexed by ``network.snapshots``. To reset the snapshots, call ``network.set_snapshots(new)``. | F3: Input (optional)
A4: snapshot_weightings | B4: pandas.DataFrame | C4: hours | D4: 1 | E4: The weightings applied to each snapshot, so that snapshots can represent more than one hour or fractions of one hour. The objective weightings are used to weight snapshots in the LOPF objective function. The store weightings determine the state of charge change for stores and storage units. The generator weightings are used when calculating global constraints. | F4: Input (optional)
A5: investment_periods | B5: pandas.Index | C5: years | D5: [] | E5: Time periods of investment. Only used for multi investment optimisation. Years have to be integer and increasing (e.g. [2025,2030,2035]). Default is an empty pd.Index([]). | F5: Input (optional)
A6: investment_period_weightings | B6: pandas.DataFrame | D6: 1 | E6: Weightings applied to each investment period. Objective weightings are multiplied with all cost coefficients in the objective function of the respective investment period (e.g. used to include social discount rate). Years weighting denote the elapsed time until the subsequent investment period (e.g. used for global constraints CO2 emissions). | F6: Input (optional)
A7: now | B7: any | D7: "now" | E7: The current snapshot/time/scenario, relevant e.g. when ``network.pf()`` is called without a snapshot argument. | F7: Input (optional)
A8: srid | B8: integer | D8: 4326 | E8: Spatial Reference System Indentifier for x,y coordinates of buses. It defaults to standard longitude and latitude. | F8: Input (optional)
A9: crs | B9: CRS-like | E9: Coordinate Reference System for the Shape components. It defaults to standard longitude and latitude, given in srid. | F9: Input (optional)
A10: buses | B10: pandas.DataFrame | E10: All static bus information compiled by PyPSA from inputs. Index is bus names, columns are bus attributes. | F10: Output
A11: buses_t | B11: dictionary of pandas.DataFrames | E11: All time-dependent bus information compiled by PyPSA from inputs. Dictionary keys are time-dependent series attributes, index is network.snapshots, columns are bus names. | F11: Output
A12: lines | B12: pandas.DataFrame | E12: All static line information compiled by PyPSA from inputs. Index is line names, columns are line attributes. | F12: Output
A13: lines_t | B13: dictionary of pandas.DataFrames | E13: All time-dependent line information compiled by PyPSA from inputs. Dictionary keys are time-dependent series attributes, index is network.snapshots, columns are line names. | F13: Output
A14: components | B14: pandas.DataFrame | E14: For each component type (buses, lines, etc.): static component information compiled by PyPSA from inputs. Index is component names, columns are component attributes. | F14: Output
A15: components_t | B15: dictionary of pandas.DataFrames | E15: For each component type (buses, lines, etc.): time-dependent component information compiled by PyPSA from inputs. Dictionary keys are time-dependent series attributes, index is network.snapshots, columns are component names. | F15: Output
A16: branches() | B16: pandas.DataFrame | E16: Dynamically generated concatenation of branch DataFrames: network.lines, network.transformers and network.links. Note that this is a copy and therefore changing entries will NOT update the original. | F16: Output
A17: graph() | B17: networkx. OrderedMultiGraph | E17: Graph of network. | F17: Output

Sheet var-stores
A1: attribute | B1: type | C1: unit | D1: default | E1: description | F1: status
A2: name | B2: string | E2: Unique name | F2: Input (required)
A3: bus | B3: string | E3: Name of bus to which store is attached. | F3: Input (required)
A4: type | B4: string | E4: Placeholder for store type. Not yet implemented. | F4: Input (optional)
A5: carrier | B5: string | E5: Energy carrier of the Store, e.g. "heat" or "gas". | F5: Input (optional)
A6: e_nom | B6: float | C6: MWh | D6: 0 | E6: Nominal energy capacity. | F6: Input (optional)
A7: e_nom_mod | B7: float | C7: MWh | D7: 0 | E7: Nominal energy capacity of the store module. | F7: Input (optional)
A8: e_nom_extendable | B8: boolean | D8: False | E8: Switch to allow capacity e_nom to be extended in OPF. | F8: Input (optional)
A9: e_nom_min | B9: float | C9: MWh | D9: 0 | E9: If e_nom is extendable in OPF, set its minimum value. | F9: Input (optional)
A10: e_nom_max | B10: float | C10: MWh | D10: inf | E10: If e_nom is extendable in OPF, set its maximum value (e.g. limited by technical potential). | F10: Input (optional)
A11: e_min_pu | B11: static or series | C11: per unit | D11: 0 | E11: Minimal value of e relative to e_nom for the OPF. | F11: Input (optional)
A12: e_max_pu | B12: static or series | C12: per unit | D12: 1 | E12: Maximal value of e relative to e_nom for the OPF. | F12: Input (optional)
A13: e_initial | B13: float | C13: MWh | D13: 0 | E13: Energy before the snapshots in the OPF. | F13: Input (optional)
A14: e_initial_per_period | B14: boolean | D14: False | E14: Switch: if True, then at the beginning of each investment period e is set to e_initial | F14: Input (optional)
A15: e_cyclic | B15: boolean | D15: False | E15: Switch: if True, then e_initial is ignored and the initial energy is set to the final energy for the group of snapshots in the OPF. | F15: Input (optional)
A16: e_cyclic_per_period | B16: boolean | D16: True | E16: Switch: if True, then the cyclic constraints are applied to each period (first snapshot level if multiindexed) separately. | F16: Input (optional)
A17: p_set | B17: static or series | C17: MW | D17: 0 | E17: active power set point (for PF) | F17: Input (optional)
A18: q_set | B18: static or series | C18: MVar | D18: 0 | E18: reactive power set point (for PF) | F18: Input (optional)
A19: sign | B19: float | D19: 1 | E19: power sign | F19: Input (optional)
A20: marginal_cost | B20: static or series | C20: currency/MWh | D20: 0 | E20: Marginal cost of production of 1 MWh. | F20: Input (optional)
A21: marginal_cost_quadratic | B21: static or series | C21: currency/MWh | D21: 0 | E21: Quadratic marginal cost of production (discharge) of 1 MWh. | F21: Input (optional)
A22: capital_cost | B22: float | C22: currency/MWh | D22: 0 | E22: Fixed period costs of extending e_nom by 1 MWh, including periodized investment costs and periodic fixed O&M costs (e.g. annuitized investment costs). | F22: Input (optional)
A23: standing_loss | B23: static or series | C23: per unit | D23: 0 | E23: Losses per hour to energy. | F23: Input (optional)
A24: build_year | B24: int | C24: year | D24: 0 | E24: build year | F24: Input (optional)
A25: lifetime | B25: float | C25: years | D25: inf | E25: lifetime | F25: Input (optional)
A26: p | B26: series | C26: MW | D26: 0 | E26: active power at bus (positive if net generation) | F26: Output
A27: q | B27: series | C27: MVar | D27: 0 | E27: reactive power (positive if net generation) | F27: Output
A28: e | B28: series | C28: MWh | D28: 0 | E28: Energy as calculated by the OPF. | F28: Output
A29: e_nom_opt | B29: float | C29: MWh | D29: 0 | E29: Optimised nominal energy capacity outputed by OPF. | F29: Output
A30: mu_upper | B30: series | C30: currency/MWh | D30: 0 | E30: Shadow price of upper e_nom limit | F30: Output
A31: mu_lower | B31: series | C31: currency/MWh | D31: 0 | E31: Shadow price of lower e_nom limit | F31: Output
A32: mu_energy_balance | B32: series | C32: currency/MWh | D32: 0 | E32: Shadow price of storage consistency equations | F32: Output
